Workbook

Sheet 주간운영
A1: 중블록 | B1: 소블록 | C1: 구분 | D1: 12월23일 | E1: 12월24일 | F1: 12월25일 | G1: 12월26일 | H1: 12월27일 | I1: 12월28일 | J1: 12월29일 | K1: 7일 평균 | L1: 이상유무(기준은 임시) | M1: 확인필요: 금일값이 평균값보다 0.9 이하, 1.1 이상
A2: 별도봉(중) | B2: 별도봉배유출 | C2: 일공급량 | D2: 9973 | E2: 9763 | F2: 9718 | G2: 9722 | H2: 9771 | I2: 10129 | J2: 10078 | K2: =AVERAGE(D2:J2) -> 9879.1429 | L2: =IF(OR(J2>=K2*1.1,J2<=K2*0.9),"확인필요","이상없음") -> 이상없음
B3: 별도봉배유출 | C3: MNF | D3: 213 | E3: 218 | F3: 224 | G3: 216 | H3: 219 | I3: 221 | J3: =MNF산정!B$440 -> 210.76667 | K3: =AVERAGE(D3:J3) -> 217.39524 | L3: =IF(OR(J3>=K3*1.1,J3<=K3*0.9),"확인필요","이상없음") -> 이상없음
B4: 별도봉1 | C4: 일공급량 | D4: 1701 | E4: 1689 | F4: 1658 | G4: 1678 | H4: 1676 | I4: 1701 | J4: 1732 | K4: =AVERAGE(D4:J4) -> 1690.7143 | L4: =IF(OR(J4>=K4*1.1,J4<=K4*0.9),"확인필요","이상없음") -> 이상없음
B5: 별도봉1 | C5: MNF | D5: 48.375017 | E5: 49.059217 | F5: 48.738783 | G5: 48.714317 | H5: 49.809417 | I5: 49.73215 | J5: =MNF산정!C$440 -> 48.5541 | K5: =AVERAGE(D5:J5) -> 48.997572 | L5: =IF(OR(J5>=K5*1.1,J5<=K5*0.9),"확인필요","이상없음") -> 이상없음
B6: 별도봉2 | C6: 일공급량 | D6: 2805 | E6: 2759 | F6: 2775 | G6: 2829 | H6: 2788 | I6: 2794 | J6: 2771 | K6: =AVERAGE(D6:J6) -> 2788.7143 | L6: =IF(OR(J6>=K6*1.1,J6<=K6*0.9),"확인필요","이상없음") -> 이상없음
B7: 별도봉2 | C7: MNF | D7: 95.257584 | E7: 95.649584 | F7: 98.652417 | G7: 97.0106 | H7: 97.231184 | I7: 95.202917 | J7: =MNF산정!D$440 -> 95.87025 | K7: =AVERAGE(D7:J7) -> 96.410648 | L7: =IF(OR(J7>=K7*1.1,J7<=K7*0.9),"확인필요","이상없음") -> 이상없음
B8: 별도봉3 | C8: 일공급량 | D8: 762 | E8: 823 | F8: 828 | G8: 857 | H8: 821 | I8: 881 | J8: 902 | K8: =AVERAGE(D8:J8) -> 839.14286 | L8: =IF(OR(J8>=K8*1.1,J8<=K8*0.9),"확인필요","이상없음") -> 이상없음
B9: 별도봉3 | C9: MNF | D9: 15.72755 | E9: 19.162 | F9: 16.911283 | G9: 16.5306 | H9: 17.13185 | I9: 17.972484 | J9: =MNF산정!E$440 -> 16.803867 | K9: =AVERAGE(D9:J9) -> 17.177091 | L9: =IF(OR(J9>=K9*1.1,J9<=K9*0.9),"확인필요","이상없음") -> 이상없음
B10: 별도봉4 | C10: 일공급량 | D10: 901 | E10: 900 | F10: 829 | G10: 840 | H10: 834 | I10: 906 | J10: 924 | K10: =AVERAGE(D10:J10) -> 876.28571 | L10: =IF(OR(J10>=K10*1.1,J10<=K10*0.9),"확인필요","이상없음") -> 이상없음
B11: 별도봉4 | C11: MNF | D11: 0 | E11: 0 | F11: 0 | G11: 0.45253563 | H11: 0 | I11: 2.6550927 | J11: =MNF산정!F$440 -> 1.9974912 | K11: =AVERAGE(D11:J11) -> 0.72930279 | L11: =IF(OR(J11>=K11*1.1,J11<=K11*0.9),"확인필요","이상없음") -> 확인필요
B12: 별도봉5 | C12: 일공급량 | D12: 798 | E12: 785 | F12: 771 | G12: 744 | H12: 782 | I12: 777 | J12: 766 | K12: =AVERAGE(D12:J12) -> 774.71429 | L12: =IF(OR(J12>=K12*1.1,J12<=K12*0.9),"확인필요","이상없음") -> 이상없음
B13: 별도봉5 | C13: MNF | D13: 17.403267 | E13: 18.313667 | F13: 18.0894 | G13: 16.417483 | H13: 17.73695 | I13: 17.288267 | J13: =MNF산정!G$440 -> 16.758617 | K13: =AVERAGE(D13:J13) -> 17.429664 | L13: =IF(OR(J13>=K13*1.1,J13<=K13*0.9),"확인필요","이상없음") -> 이상없음
B14: 별도봉6 | C14: 일공급량 | D14: 0 | E14: 0 | F14: 0 | G14: 0 | H14: 0 | I14: 0 | J14: 0 | K14: =AVERAGE(D14:J14) -> 0 | L14: =IF(OR(J14>=K14*1.1,J14<=K14*0.9),"확인필요","이상없음") -> 확인필요
B15: 별도봉6 | C15: MNF | D15: 0 | E15: 0 | F15: 0 | G15: 0 | H15: 0 | I15: 0 | K15: =AVERAGE(D15:J15) -> 0 | L15: =IF(OR(J15>=K15*1.1,J15<=K15*0.9),"확인필요","이상없음") -> 확인필요
A16: 사라봉1(중) | B16: 건입저지대2 | C16: 일공급량 | D16: 10200 | E16: 9681 | F16: 9627 | G16: 9625 | H16: 9749 | I16: 9860 | J16: 9713 | K16: =AVERAGE(D16:J16) -> 9779.2857 | L16: =IF(OR(J16>=K16*1.1,J16<=K16*0.9),"확인필요","이상없음") -> 이상없음
B17: 건입저지대2 | C17: MNF | D17: 306.03333 | E17: 306.21667 | F17: 298.61667 | G17: 299.16667 | H17: 308.4 | I17: 304.76667 | J17: =MNF산정!H$440 -> 304.58333 | K17: =AVERAGE(D17:J17) -> 303.96905 | L17: =IF(OR(J17>=K17*1.1,J17<=K17*0.9),"확인필요","이상없음") -> 이상없음
B18: 건입저지대 | C18: 일공급량 | D18: 9264 | E18: 8808 | F18: 8760 | G18: 8747 | H18: 8859 | I18: 8963 | J18: 8847 | K18: =AVERAGE(D18:J18) -> 8892.5714 | L18: =IF(OR(J18>=K18*1.1,J18<=K18*0.9),"확인필요","이상없음") -> 이상없음
B19: 건입저지대 | C19: MNF | D19: 271.51667 | E19: 273.35 | F19: 265.96667 | G19: 267.46667 | H19: 275.55 | I19: 272.61667 | J19: =MNF산정!I$440 -> 271.93333 | K19: =AVERAGE(D19:J19) -> 271.2 | L19: =IF(OR(J19>=K19*1.1,J19<=K19*0.9),"확인필요","이상없음") -> 이상없음
B20: 사라봉1 | C20: 일공급량 | D20: 2013 | E20: 2012 | F20: 2013 | G20: 2007 | H20: 2014 | I20: 2025 | J20: 2046 | K20: =AVERAGE(D20:J20) -> 2018.5714 | L20: =IF(OR(J20>=K20*1.1,J20<=K20*0.9),"확인필요","이상없음") -> 이상없음
B21: 사라봉1 | C21: MNF | D21: 58.71785 | E21: 60.442483 | F21: 58.9854 | G21: 59.827967 | H21: 58.764933 | I21: 58.847833 | J21: =MNF산정!J$440 -> 60.44625 | K21: =AVERAGE(D21:J21) -> 59.433245 | L21: =IF(OR(J21>=K21*1.1,J21<=K21*0.9),"확인필요","이상없음") -> 이상없음
B22: 사라봉2 | C22: 일공급량 | D22: 1807 | E22: 1804 | F22: 1802 | G22: 1838 | H22: 1787 | I22: 1850 | J22: 1797 | K22: =AVERAGE(D22:J22) -> 1812.1429 | L22: =IF(OR(J22>=K22*1.1,J22<=K22*0.9),"확인필요","이상없음") -> 이상없음
B23: 사라봉2 | C23: MNF | D23: 59.192994 | E23: 60.590926 | F23: 59.158357 | G23: 59.172294 | H23: 61.317236 | I23: 60.419417 | J23: =MNF산정!K$440 -> 60.400438 | K23: =AVERAGE(D23:J23) -> 60.035952 | L23: =IF(OR(J23>=K23*1.1,J23<=K23*0.9),"확인필요","이상없음") -> 이상없음
B24: 사라봉3 | C24: 일공급량 | D24: 1874 | E24: 1646 | F24: 1713 | G24: 1747 | H24: 1701 | I24: 1754 | J24: 1734 | K24: =AVERAGE(D24:J24) -> 1738.4286 | L24: =IF(OR(J24>=K24*1.1,J24<=K24*0.9),"확인필요","이상없음") -> 이상없음
B25: 사라봉3 | C25: MNF | D25: 41.34785 | E25: 41.98985 | F25: 41.553967 | G25: 40.8559 | H25: 42.14 | I25: 42.216667 | J25: =MNF산정!L$440 -> 43.447734 | K25: =AVERAGE(D25:J25) -> 41.935995 | L25: =IF(OR(J25>=K25*1.1,J25<=K25*0.9),"확인필요","이상없음") -> 이상없음
B26: 사라봉4 | C26: 일공급량 | D26: 443 | E26: 445 | F26: 447 | G26: 428 | H26: 456 | I26: 448 | J26: 442 | K26: =AVERAGE(D26:J26) -> 444.14286 | L26: =IF(OR(J26>=K26*1.1,J26<=K26*0.9),"확인필요","이상없음") -> 이상없음
B27: 사라봉4 | C27: MNF | D27: 11.987883 | E27: 13.0453 | F27: 11.788117 | G27: 13.12625 | H27: 12.8945 | I27: 12.362917 | J27: =MNF산정!M$440 -> 11.833283 | K27: =AVERAGE(D27:J27) -> 12.434036 | L27: =IF(OR(J27>=K27*1.1,J27<=K27*0.9),"확인필요","이상없음") -> 이상없음
B28: 사라봉5 | C28: 일공급량 | D28: 477 | E28: 465 | F28: 449 | G28: 445 | H28: 449 | I28: 424 | J28: 432 | K28: =AVERAGE(D28:J28) -> 448.71429 | L28: =IF(OR(J28>=K28*1.1,J28<=K28*0.9),"확인필요","이상없음") -> 이상없음
B29: 사라봉5 | C29: MNF | D29: 16.8284 | E29: 18.655267 | F29: 17.064767 | G29: 19.157816 | H29: 16.668284 | I29: 16.172067 | J29: =MNF산정!N$440 -> 17.025584 | K29: =AVERAGE(D29:J29) -> 17.367455 | L29: =IF(OR(J29>=K29*1.1,J29<=K29*0.9),"확인필요","이상없음") -> 이상없음
A30: 사라봉2(중) | B30: 건입고지대 | C30: 일공급량 | D30: 684 | E30: 719 | F30: 654 | G30: 671 | H30: 729 | I30: 709 | J30: 738 | K30: =AVERAGE(D30:J30) -> 700.57143 | L30: =IF(OR(J30>=K30*1.1,J30<=K30*0.9),"확인필요","이상없음") -> 이상없음
B31: 건입고지대 | C31: MNF | D31: 15.783333 | E31: 15.433333 | F31: 15.35 | G31: 15.466667 | H31: 15.766667 | I31: 16.5 | J31: =MNF산정!O$440 -> 16.433333 | K31: =AVERAGE(D31:J31) -> 15.819048 | L31: =IF(OR(J31>=K31*1.1,J31<=K31*0.9),"확인필요","이상없음") -> 이상없음
B32: 건입고지대2 | C32: 일공급량 | D32: 0 | E32: 0 | F32: 0 | G32: 0 | H32: 0 | I32: 0 | J32: 0 | K32: =AVERAGE(D32:J32) -> 0 | L32: =IF(OR(J32>=K32*1.1,J32<=K32*0.9),"확인필요","이상없음") -> 확인필요
B33: 건입고지대2 | C33: MNF | D33: 0 | E33: 0 | F33: 0 | G33: 0 | H33: 0 | I33: 0 | J33: =MNF산정!P$440 -> 0 | K33: =AVERAGE(D33:J33) -> 0 | L33: =IF(OR(J33>=K33*1.1,J33<=K33*0.9),"확인필요","이상없음") -> 확인필요
B34: 사라봉6 | C34: 일공급량 | D34: 700 | E34: 736 | F34: 671 | G34: 686 | H34: 746 | I34: 726 | J34: 756 | K34: =AVERAGE(D34:J34) -> 717.28571 | L34: =IF(OR(J34>=K34*1.1,J34<=K34*0.9),"확인필요","이상없음") -> 이상없음
B35: 사라봉6 | C35: MNF | D35: 16.119424 | E35: 15.766542 | F35: 15.767655 | G35: 16.076501 | H35: 16.109717 | I35: 16.885083 | J35: =MNF산정!Q$440 -> 16.788744 | K35: =AVERAGE(D35:J35) -> 16.216238 | L35: =IF(OR(J35>=K35*1.1,J35<=K35*0.9),"확인필요","이상없음") -> 이상없음
A36: 사라봉3(중) | B36: 영락교회유출 | C36: 일공급량 | D36: 947 | E36: 943 | F36: 904 | G36: 905 | H36: 924 | I36: 964 | J36: 1022 | K36: =AVERAGE(D36:J36) -> 944.14286 | L36: =IF(OR(J36>=K36*1.1,J36<=K36*0.9),"확인필요","이상없음") -> 이상없음
B37: 영락교회유출 | C37: MNF | D37: 1.8160937 | E37: 5.6987499 | F37: 1.9328125 | G37: 7.25 | H37: 5.5660937 | I37: 8.3001563 | J37: =MNF산정!R$440 -> 4.1324999 | K37: =AVERAGE(D37:J37) -> 4.9566294 | L37: =IF(OR(J37>=K37*1.1,J37<=K37*0.9),"확인필요","이상없음") -> 확인필요
B38: 사라봉7 | C38: 일공급량 | D38: 996 | E38: 994 | F38: 947 | G38: 955 | H38: 966 | I38: 1007 | J38: 1073 | K38: =AVERAGE(D38:J38) -> 991.14286 | L38: =IF(OR(J38>=K38*1.1,J38<=K38*0.9),"확인필요","이상없음") -> 이상없음
B39: 사라봉7 | C39: MNF | D39: 3.7130124 | E39: 6.3389445 | F39: 3.3029585 | G39: 7.1748364 | H39: 5.5900077 | I39: 8.1410752 | J39: =MNF산정!S$440 -> 4.9219543 | K39: =AVERAGE(D39:J39) -> 5.5975413 | L39: =IF(OR(J39>=K39*1.1,J39<=K39*0.9),"확인필요","이상없음") -> 확인필요
A40: 사라봉4(중) | B40: 공원유출 | C40: 일공급량 | D40: 140 | E40: 134 | F40: 134 | G40: 131 | H40: 131 | I40: 124 | J40: 131 | K40: =AVERAGE(D40:J40) -> 132.14286 | L40: =IF(OR(J40>=K40*1.1,J40<=K40*0.9),"확인필요","이상없음") -> 이상없음
...

Sheet 운영일보
A1: 대블록 | B1: 중블록 | C1: 소블록 | D1: 25년12월28일 일요일
E2: 이동평균으로 산정함 | F2: 이동평균 | G2: 1분단위 데이터의 1시간 평균값 을 5분단위로 산출후 가장 작은값
D3: 일공급량/(전일) | E3: MNF(야간최소유량) (당일 00시 ~06시) | F3: 순시 야간최소유량 | G3: 1분단위 순시유량 중 3~8번째로 작은 데이터의 평균값
A4: 중앙(대) | B4: 별도봉(중)
C5: 별도봉배유출 | D5: 10080 | E5: =MNF산정!EG4 -> 210.76667
C6: 별도봉1 | D6: 1732 | E6: =MNF산정!EG5 -> 48.5541
C7: 별도봉2 | D7: 2772 | E7: =MNF산정!EG6 -> 95.87025
C8: 별도봉3 | D8: 901 | E8: =MNF산정!EG7 -> 16.803867
C9: 별도봉4 | D9: 924 | E9: =MNF산정!EG8 -> 1.9974912
C10: 별도봉5 | D10: 766 | E10: =MNF산정!EG9 -> 16.758617
B11: 사라봉1(중) | C11: 건입저지대2 | D11: 738 | E11: =MNF산정!EG10 -> 304.58333
C12: 건입저지대 | D12: 0 | E12: =MNF산정!EG11 -> 271.93333
C13: 사라봉1 | D13: 2046 | E13: =MNF산정!EG12 -> 60.44625
C14: 사라봉2 | D14: 1797 | E14: =MNF산정!EG13 -> 60.400438
C15: 사라봉3 | D15: 1734 | E15: =MNF산정!EG14 -> 43.447734
C16: 사라봉4 | D16: 442 | E16: =MNF산정!EG15 -> 11.833283
C17: 사라봉5 | D17: 432 | E17: =MNF산정!EG16 -> 17.025584
B18: 사라봉2(중) | C18: 건입고지대 | D18: 9714 | E18: =MNF산정!EG17 -> 16.433333
C19: 건입고지대2 | D19: 8848 | E19: =MNF산정!EG18 -> 0
C20: 사라봉6 | D20: 756 | E20: =MNF산정!EG19 -> 16.788744
B21: 사라봉3(중) | C21: 영락교회유출 | D21: 1022 | E21: =MNF산정!EG20 -> 4.1324999
C22: 사라봉7 | D22: 1073 | E22: =MNF산정!EG21 -> 4.9219543
B23: 사라봉4(중) | C23: 공원유출 | D23: 131 | E23: =MNF산정!EG22 -> 4.45
C24: 사라봉8 | D24: 131 | E24: =MNF산정!EG23 -> 4.45
B25: 영평1(중) | C25: 영평배시내유출 | D25: 31314 | E25: =MNF산정!EG24 -> 843.75
C26: 영평1 | D26: 1132 | E26: =MNF산정!EG25 -> 25.568622
C27: 영평2 | D27: 891 | E27: =MNF산정!EG26 -> 24.4398
C28: 영평3 | D28: 341 | E28: =MNF산정!EG27 -> 6.05485
C29: 영평4 | D29: 0 | E29: =MNF산정!EG28 -> 0
C30: 영평5 | D30: 764 | E30: =MNF산정!EG29 -> 18.383517
C31: 영평6 | D31: 0 | E31: =MNF산정!EG30 -> 0
C32: 영평7 | D32: 1878 | E32: =MNF산정!EG31 -> 51.320356
C33: 영평8 | D33: 168 | E33: =MNF산정!EG32 -> 5.9031001
C34: 영평9 | D34: 111 | E34: =MNF산정!EG33 -> 0
C35: 영평10 | D35: 2697 | E35: =MNF산정!EG34 -> 79.630315
C36: 영평11 | D36: 1405 | E36: =MNF산정!EG35 -> 0
C37: 영평12 | D37: 2390 | E37: =MNF산정!EG36 -> 59.83603
... C42: 영평18 | D42: 1676 | E42: =MNF산정!EG41 -> 54.743183
B43: 아라가(중) | C43: 아라가배유출 | D43: 5128 | E43: =MNF산정!EG42 -> 111.68854
C44: 아라가1,2유입 | D44: 2929 | E44: =MNF산정!EG43 -> 56.783333
...

Sheet MNF산정
A1: 중앙(대) | BN1: 삼양 대블록 | CD1: 신제주 대블록
A2: 별도봉(중) | H2: 사라봉1(중) | O2: 사라봉2(중) | R2: 사라봉3(중) | T2: 사라봉4(중) | V2: 영평1(중) | AN2: 아라가(중) | AR2: 산천단1(중) | AV2: 산천단2(중) | AX2: 영평2(중) | AZ2: 영평소(중) | BB2: 아라배(중) | BD2: 관음사(중) | BF2: 월평(중) | BG2: 월평지선(중) | BJ2: 고다시(중) | BM2: 어승생1(중) | BN2: 도련취수원 | BQ2: 도련(중) | BV2: 명도암(중) | BW2: 봉개(중) | BX2: 용강(중) | BY2: 절물1(중) | CA2: 절물2(중) | CC2: 어승생2(중) | CD2: 민오름(중) | CM2: 염통(중) | CW2: 월산(중) | DJ2: 오라중 | DP2: 사라마을 | DR2: 정실4(중) | DT2: 정실6(중) | DX2: 해안마을 | DZ2: 해안지선
A3: =IFERROR(DATEVALUE(SUBSTITUTE(SUBSTITUTE(SUBSTITUTE(SUBSTITUTE(LEFT(운영일보!D1,9),"년","-"),"월","-"),"일",""),".","-")),운영일보!D1) +1 -> 46020 | B3: 별도봉(배)유출 | C3: 별도봉1 | D3: 별도봉2 | E3: 별도봉3 | F3: 별도봉4 | G3: 별도봉5 | H3: 건입 저지대2 | I3: 건입 저지대 | J3: 사라봉1 | K3: 사라봉2 | L3: 사라봉3 | M3: 사라봉4 | N3: 사라봉5 | O3: 건입 고지대 | P3: 건입 고지대2 | Q3: 사라봉6 | R3: 영락교회유출 | S3: 사라봉7 | T3: 공원 유출 | U3: 사라봉8 | V3: 영평(배) 유출 | W3: 영평1 | X3: 영평2 | Y3: 영평3 | Z3: 영평4 | AA3: 영평5 | AB3: 영평6 | AC3: 영평7 | AD3: 영평8 | AE3: 영평9 | AF3: 영평10 | AG3: 영평11 | AH3: 영평12 | AI3: 영평13 | AJ3: 영평14 | AK3: 영평16 | AL3: 영평17 | AM3: 영평18 | AN3: 아라가(배) 유출 | AO3: 아라가1,2 유입 | AP3: 아라가1 | AQ3: 아라가2 | AR3: 산천단 법원 유출 | AS3: 산천단1 (#1) | AT3: 산천단 제대 유출 | AU3: 산천단1 (#2) | AV3: 산천단 첨단 유출 | AW3: 산천단2 | AX3: 황세앗 유출 | AY3: 영평15 | AZ3: 영평소 (배)유출 | BA3: 영평소 | BB3: 아라2지구 구남유출 | BC3: 아라2지구 | BD3: 관음사 | BE3: 관음사 | BF3: 월평(소) | BG3: 월평지선 | BH3: 월평지선(신규) | BI3: 중소블록 | BJ3: 합 | BK3: 고다시 직송 | BL3: 제대직송 (유수암) | BM3: 어승생1 | BN3: 취수합 | BO3: 도련1호 | BP3: 도련2호 | BQ3: 도련(정) 유출 | BR3: 도련1 | BS3: 도련2 | BT3: 도련3 | BU3: 도련4 | BV3: 명도암(배) 유출 | BW3: 봉개(배) 유출 | BX3: 용강(배) 유출 | BY3: 명도암 | BZ3: 절물01 | CA3: 노루생태 공원 | CB3: 절물02 | CC3: 어승생2 | CD3: 민오름 (합동청사) | CE3: 민오름1 | CF3: 민오름5 | CG3: 동부도남 유출 | CH3: 동부오라 유출 | CI3: 신제주 | CJ3: 민오름2 | CK3: 민오름3 | CL3: 민오름04 (연미마을) | CM3: 염통구(배) 유출 | CN3: 염통6 | CO3: 염통7 | CP3: 염통8 | CQ3: 염통신(배) 유출 | CR3: 염통1 | CS3: 염통2 | CT3: 염통3 | CU3: 염통4 | CV3: 염통5 | CW3: 외도배 계명동 유출 | CX3: 월산신(배) 광평유출 | CY3: 월산1 | CZ3: 월산2 | DA3: 월산3 | DB3: 월산4 | DC3: 월산5 | DD3: 월산구(배) 시내유출 | DE3: 월산신배시내유출 | DF3: 월산6 | DG3: 월산7 | DH3: 월산8 | DI3: 월산9 | DJ3: 오라(배) 유출 | DK3: 오라 유입 | DL3: 오라1 | DM3: 오라2 | DN3: 오라3 | DO3: 오라4 | DP3: 사라마을 | DR3: 정실4취수 | DS3: 정실4 | DT3: 정실6취수 | DV3: 노형조절지 2유출 | DW3: 드림타워 | DX3: 해안동배유출 | DZ3: 해안동 | EA3: 축산마을 | EB3: F534 (관정) | EC3: F535 (관정) | ED3: 월산배통합유출 | EE3: 계측값 순간 최소값 | EF3: 최소값 3~8번째 평균 | EG3: MNF
A4: =A3 + TIME(,,) -> 46020 | B4: 327 | C4: 55.191002 | D4: 106.424 | E4: 24.429001 | F4: 1.9413044 | G4: 24.089001 | H4: 385 | I4: 350 | J4: 82.334 | K4: 65.55899 | L4: 53.014 | M4: 16.285999 | N4: 17.113001 | O4: 21 | P4: 0 | Q4: 21.818468 | R4: 31.003124 | S4: 33.283222 | T4: 9 | U4: 9 | V4: 1272 | W4: 46.675468 | X4: 40.601002 | Y4: 10.051 | Z4: 0 | AA4: 31.893 | AB4: 0 | AC4: 70.456818 | AD4: 6.3610001 | AE4: 2.1411426 | AF4: 99.829971 | AG4: 0 | AH4: 92.86142 | AI4: 22.646999 | AJ4: 44.001358 | AK4: 54.099869 | AL4: 63.087002 | AM4: 60.181 | AN4: 180.25 | AO4: 99 | AP4: 95.580605 | AQ4: 64.275604 | AR4: 136 | AT4: 117 | AV4: 91 | AX4: 38 | AY4: 41.200798 | AZ4: 31 | BB4: 206 | BC4: 212.7868 | BD4: 7.5999999 | BE4: 7.6386127 | BF4: 31 | BG4: 12 | BH4: 12.700912 | BJ4: =SUM(BK4:BL4) -> 20 | BK4: 20 | BL4: 0 | BN4: =SUM(BO4:BP4) -> 124 | BO4: 75 | BP4: 49 | BQ4: 360 | BR4: 111.74 | BS4: 27.990999 | BT4: 52.299999 | BU4: 51.974998 | BV4: 69 | BW4: 7.5 | BX4: 13.8 | BY4: 28 | BZ4: 0.013609146 | CA4: 0 | CB4: 30.095642 | CD4: 454.37875 | CE4: 90.923386 | CF4: 36.917484 | CG4: 35.338192 | CH4: 303.94885 | CI4: 124.39034 | CJ4: 61.583721 | CK4: 68.904427 | CL4: 53.65596 | CM4: 346.15985 | CN4: 111.31422 | CO4: 103.29364 | CP4: 129.72234 | CQ4: 0 | CR4: 76.439835 | CS4: 17.765982 | CT4: 63.238724 | CU4: 289.61368 | CV4: 120.16051 | CW4: 7 | CX4: 515 | CY4: 241.77457 | CZ4: 68.469238 | DA4: 30.117266 | DB4: 50.320038 | DC4: 100.72842 | DD4: 182 | DE4: 193 | DF4: 142.72212 | DG4: 120.2774 | DH4: 92.627182 | DI4: 50.569054 | DJ4: 263 | DK4: 157.261 | DL4: 34.720001 | DM4: 65.384003 | DN4: 56.902 | DO4: 117.59358 | DP4: 17.586 | DR4: 67 | DS4: 53.700001 | DT4: 13 | DV4: 175 | DW4: 165.26762 | DX4: 12 | DZ4: 55 | EA4: 3 | EB4: 0 | EC4: 1 | ED4: 380.10001 | EE4: {=TRANSPOSE(B364:ED364)} -> 205 | EF4: {=TRANSPOSE(B366:ED366)} -> 206.33333 | EG4: {=TRANSPOSE(B440:ED440)} -> 210.76667 | EH4: 별도봉배유출
A5: =A4 + TIME(,1,) -> 46020.001 | B5: 327 | C5: 57.566002 | D5: 107.781 | E5: 24.768 | F5: 5.8796902 | G5: 24.881001 | H5: 382 | I5: 347 | J5: 79.507004 | K5: 67.272842 | L5: 52.484001 | M5: 17.077 | N5: 17.558001 | O5: 20 | P5: 0 | Q5: 22.921381 | R5: 31.003124 | S5: 33.136654 | T5: 9 | U5: 9 | V5: 1260 | W5: 46.411533 | X5: 40.487999 | Y5: 10.115 | Z5: 0 | AA5: 33.476002 | AB5: 0 | AC5: 71.00988 | AD5: 6.3610001 | AE5: 1.5827018 | AF5: 99.760643 | AG5: 0 | AH5: 90.826431 | AI5: 23.538 | AJ5: 42.612644 | AK5: 54.129055 | AL5: 61.143002 | AM5: 61.071999 | AN5: 177.6875 | AO5: 99 | AP5: 95.498978 | AQ5: 62.692444 | AR5: 136 | AT5: 117 | AV5: 97 | AX5: 38 | AY5: 40.946186 | AZ5: 30 | BB5: 204 | BC5: 209.63387 | BD5: 7.5999999 | BE5: 7.6342926 | BF5: 31 | BG5: 12 | BH5: 13.100147 | BJ5: =SUM(BK5:BL5) -> 20 | BK5: 20 | BL5: 0 | BN5: =SUM(BO5:BP5) -> 125 | BO5: 76 | BP5: 49 | BQ5: 374 | BR5: 119.204 | BS5: 29.009001 | BT5: 60.265999 | BU5: 54.391998 | BV5: 69.300003 | BW5: 7.5 | BX5: 13.7 | BY5: 28 | BZ5: 0.013483216 | CA5: 0 | CB5: 30.136156 | CD5: 456.51697 | CE5: 90.489731 | CF5: 36.394482 | CG5: 35.338192 | CH5: 303.48041 | CI5: 124.01706 | CJ5: 59.62529 | CK5: 69.292671 | CL5: 53.032066 | CM5: 346.19418 | CN5: 113.16154 | CO5: 103.29364 | CP5: 126.55125 | CQ5: 0 | CR5: 72.828316 | CS5: 16.38763 | CT5: 62.45002 | CU5: 282.7709 | CV5: 119.77897 | CW5: 4 | CX5: 511 | CY5: 239.13156 | CZ5: 69.523865 | DA5: 29.711782 | DB5: 49.101257 | DC5: 97.936836 | DD5: 170 | DE5: 193 | DF5: 140.79503 | DG5: 119.96899 | DH5: 94.241486 | DI5: 48.154118 | DJ5: 260 | DK5: 154.20799 | DL5: 32.910999 | DM5: 63.617001 | DN5: 55.841 | DO5: 117.62468 | DP5: 17.388 | DR5: 67 | DS5: 53.799999 | DT5: 14 | DV5: 172 | DW5: 165.59506 | DX5: 12 | DZ5: 55 | EA5: 3 | EB5: 0 | EC5: 1 | ED5: 381 | EE5: 43.09 | EF5: 44.880333 | EG5: 48.5541 | EH5: 별도봉1
A6: =A5 + TIME(,1,) -> 46020.001 | B6: 331 | C6: 57.452999 | D6: 106.424 | E6: 23.863001 | F6: 5.5840168 | G6: 23.863001 | H6: 380 | I6: 344 | J6: 77.471001 | K6: 66.979111 | L6: 54.958 | M6: 16.964001 | N6: 17.493999 | O6: 20 | P6: 0 | Q6: 21.18894 | R6: 31.003124 | S6: 31.832058 | T6: 9 | U6: 9 | V6: 1262 | W6: 44.760006 | X6: 40.941002 | Y6: 11.005 | Z6: 0 | AA6: 35.737999 | AB6: 0 | AC6: 70.867462 | AD6: 6.1069999 | AE6: 1.6193759 | AF6: 102.10349 | AG6: 0 | AH6: 90.595047 | AI6: 24.556 | AJ6: 43.203133 | AK6: 52.356297 | AL6: 61.849998 | AM6: 60.436001 | AN6: 183.8125 | AO6: 101 | AP6: 94.795807 | AQ6: 64.939125 | AR6: 138 | AT6: 117 | AV6: 96 | AX6: 41 | AY6: 42.143414 | AZ6: 30 | BB6: 208 | BC6: 214.97639 | BD6: 7.5999999 | BE6: 7.6159019 | BF6: 31 | BG6: 13 | BH6: 13.322619 | BJ6: =SUM(BK6:BL6) -> 21 | BK6: 21 | BL6: 0 | BN6: =SUM(BO6:BP6) -> 124.2 | BO6: 75 | BP6: 49.200001 | BQ6: 365 | BR6: 118.752 | BS6: 31.808001 | BT6: 60.265999 | BU6: 54.838001 | BV6: 68.400002 | BW6: 7.5999999 | BX6: 13.7 | BY6: 29 | BZ6: 0.014215666 | CA6: 0 | CB6: 30.11495 | CD6: 425.09781 | CE6: 59.075359 | CF6: 37.035278 | CG6: 35.338192 | CH6: 303.66956 | CI6: 125.56074 | CJ6: 59.956425 | CK6: 69.747986 | CL6: 51.395817 | CM6: 350.14957 | CN6: 112.92941 | CO6: 105.12988 | CP6: 129.35239 | CQ6: 0 | CR6: 72.279976 | CS6: 15.467538 | CT6: 58.079601 | CU6: 283.96848 | CV6: 122.38766 | CW6: 7 | CX6: 507 | CY6: 245.25677 | CZ6: 68.824104 | DA6: 30.789299 | DB6: 50.387745 | DC6: 98.462128 | DD6: 181 | DE6: 195 | DF6: 141.54713 | DG6: 119.84387 | DH6: 93.376816 | DI6: 48.076981 | DJ6: 265 | DK6: 163.114 | DL6: 32.910999 | DM6: 65.029999 | DN6: 58.139 | DO6: 118.28616 | DP6: 18.039 | DR6: 67 | DS6: 53.099998 | DT6: 13 | DV6: 176 | DW6: 165.90367 | DX6: 15 | DZ6: 54 | EA6: 3 | EB6: 0 | EC6: 1 | ED6: 380.10001 | EE6: 94.662003 | EF6: 95.019833 | EG6: 95.87025 | EH6: 별도봉2
A7: =A6 + TIME(,1,) -> 46020.002 | B7: 330 | C7: 57.566002 | D7: 105.632 | E7: 21.714001 | F7: 5.3506393 | G7: 24.429001 | H7: 381 | I7: 346 | J7: 77.471001 | K7: 66.30526 | L7: 55.133999 | M7: 15.946 | N7: 17.24 | O7: 19 | P7: 0 | Q7: 19.724405 | R7: 31.003124 | S7: 31.832058 | T7: 9 | U7: 9 | V7: 1273 | W7: 45.383816 | X7: 41.054001 | Y7: 12.596 | Z7: 0 | AA7: 36.756001 | AB7: 0 | AC7: 70.557152 | AD7: 6.1069999 | AE7: 1.7606207 | AF7: 101.36311 | AG7: 0 | AH7: 89.295502 | AI7: 24.492001 | AJ7: 43.738506 | AK7: 53.627823 | AL7: 64.147003 | AM7: 63.617001 | AN7: 180.25 | AO7: 103 | AP7: 95.817039 | AQ7: 64.914795 | AR7: 137 | AT7: 118 | AV7: 97 | AX7: 41 | AY7: 42.143414 | AZ7: 30 | BB7: 208 | BC7: 214.14268 | BD7: 7.5 | BE7: 7.5945039 | BF7: 31 | BG7: 13 | BH7: 13.339046 | BJ7: =SUM(BK7:BL7) -> 21 | BK7: 21 | BL7: 0 | BN7: =SUM(BO7:BP7) -> 126 | BO7: 77 | BP7: 49 | BQ7: 363 | BR7: 121.918 | BS7: 31.045 | BT7: 54.723999 | BU7: 53.82 | BV7: 69.300003 | BW7: 7.5999999 | BX7: 13.7 | BY7: 29 | BZ7: 0.015724344 | CA7: 0 | CB7: 29.86635 | CD7: 427.65228 | CE7: 58.855537 | CF7: 36.792671 | CG7: 35.338192 | CH7: 304.45731 | CI7: 127.15598 | CJ7: 62.42218 | CK7: 70.219994 | CL7: 51.577309 | CM7: 356.10175 | CN7: 118.33569 | CO7: 103.10715 | CP7: 130.55673 | CQ7: 0 | CR7: 73.994835 | CS7: 16.588621 | CT7: 61.459347 | CU7: 283.51529 | CV7: 123.79505 | CW7: 8 | CX7: 509 | CY7: 241.22997 | CZ7: 68.814049 | DA7: 30.666435 | DB7: 49.08569 | DC7: 99.626282 | DD7: 180 | DE7: 194 | DF7: 144.58269 | DG7: 116.345 | DH7: 93.005272 | DI7: 48.076054 | DJ7: 264 | DK7: 156.752 | DL7: 30.535999 | DM7: 64.147003 | DN7: 59.199001 | DO7: 121.00259 | DP7: 18.039 | DR7: 67 | DS7: 53.799999 | DT7: 13 | DV7: 176 | DW7: 165.62209 | DX7: 12 | DZ7: 55 | EA7: 3 | EB7: 0 | EC7: 1 | ED7: 374.29999 | EE7: 12.553 | EF7: 14.494833 | EG7: 16.803867 | EH7: 별도봉3
A8: =A7 + TIME(,1,) -> 46020.003 | B8: 330 | C8: 58.244999 | D8: 107.555 | E8: 22.052999 | F8: 12.263926 | G8: 23.410999 | H8: 382 | I8: 337 | J8: 79.733002 | K8: 63.789478 | L8: 53.543999 | M8: 17.077 | N8: 16.731001 | O8: 21 | P8: 0 | Q8: 21.860464 | R8: 31.003124 | S8: 32.121559 | T8: 9 | U8: 9 | V8: 1260 | W8: 42.250793 | X8: 42.298 | Y8: 12.023 | Z8: 0 | AA8: 34.493999 | AB8: 0 | AC8: 69.046646 | AD8: 5.8520002 | AE8: 1.8334569 | AF8: 101.61529 | AG8: 0 | AH8: 90.828827 | AI8: 19.975 | AJ8: 42.064011 | AK8: 55.658428 | AL8: 64.323997 | AM8: 62.408001 | AN8: 177.0625 | AO8: 96 | AP8: 94.633484 | AQ8: 60.956287 | AR8: 137 | AT8: 117 | AV8: 88 | AX8: 38 | AY8: 40.492413 | AZ8: 30 | BB8: 206 | BC8: 213.45374 | BD8: 7.5 | BE8: 7.5856075 | BF8: 31 | BG8: 13 | BH8: 13.486877 | BJ8: =SUM(BK8:BL8) -> 21 | BK8: 21 | BL8: 0 | BN8: =SUM(BO8:BP8) -> 125 | BO8: 76 | BP8: 49 | BQ8: 362 | BR8: 119.656 | BS8: 29.009001 | BT8: 57.494999 | BU8: 52.547001 | BV8: 69.900002 | BW8: 7.6999998 | BX8: 13.7 | BY8: 29 | BZ8: 0.013812804 | CA8: 1 | CB8: 29.513769 | CD8: 424.52277 | CE8: 59.408321 | CF8: 37.090515 | CG8: 35.338192 | CH8: 304.8313 | CI8: 128.06587 | CJ8: 63.491489 | CK8: 67.892014 | CL8: 52.020775 | CM8: 358.25623 | CN8: 120.2732 | CO8: 103.76763 | CP8: 125.39114 | CQ8: 0 | CR8: 73.429665 | CS8: 14.822356 | CT8: 60.383862 | CU8: 282.55191 | CV8: 122.87729 | CW8: 3 | CX8: 510 | CY8: 243.3204 | CZ8: 71.414879 | DA8: 31.445829 | DB8: 53.661598 | DC8: 96.888046 | DD8: 162 | DE8: 193 | DF8: 143.03088 | DG8: 116.73394 | DH8: 93.120033 | DI8: 48.347523 | DJ8: 266 | DK8: 158.27901 | DL8: 31.780001 | DM8: 65.914001 | DN8: 58.668999 | DO8: 121.7524 | DP8: 17.728001 | DR8: 67 | DS8: 53.5 | DT8: 13 | DV8: 174 | DW8: 166.20468 | DX8: 13 | DZ8: 55 | EA8: 3 | EB8: 0 | EC8: 1 | ED8: 373.39999 | EE8: 0 | EF8: 0 | EG8: 1.9974912 | EH8: 별도봉4
A9: =A8 + TIME(,1,) -> 46020.003 | B9: 321 | C9: 59.827999 | D9: 103.823 | E9: 21.827 | F9: 11.437412 | G9: 22.958 | H9: 379 | I9: 346 | J9: 79.280998 | K9: 63.734745 | L9: 50.540001 | M9: 16.399 | N9: 17.621 | O9: 21 | P9: 0 | Q9: 21.810488 | R9: 30 | S9: 31.401232 | T9: 9 | U9: 9 | V9: 1280 | W9: 40.179852 | X9: 42.976002 | Y9: 11.578 | Z9: 0 | AA9: 37.435001 | AB9: 0 | AC9: 69.292038 | AD9: 5.8520002 | AE9: 1.6132298 | AF9: 101.16129 | AG9: 0 | AH9: 97.176323 | AI9: 21.311001 | AJ9: 47.502251 | AK9: 57.15398 | AL9: 61.673 | AM9: 62.661999 | AN9: 170.875 | AO9: 95 | AP9: 91.879913 | AQ9: 58.817734 | AR9: 137 | AT9: 118 | AV9: 90 | AX9: 38 | AY9: 40.148674 | AZ9: 30 | BB9: 208 | BC9: 213.10622 | BD9: 7.5 | BE9: 7.5745578 | BF9: 31 | BG9: 13 | BH9: 13.339968 | BJ9: =SUM(BK9:BL9) -> 20 | BK9: 20 | BL9: 0 | BN9: =SUM(BO9:BP9) -> 124 | BO9: 75 | BP9: 49 | BQ9: 361 | BR9: 112.871 | BS9: 28.246 | BT9: 56.803001 | BU9: 53.056 | BV9: 69.099998 | BW9: 7.5 | BX9: 13.7 | BY9: 29 | BZ9: 0.0134319 | CA9: 0 | CB9: 29.513769 | CD9: 424.62515 | CE9: 60.631878 | CF9: 36.109543 | CG9: 35.338192 | CH9: 304.02203 | CI9: 127.34636 | CJ9: 62.950378 | CK9: 67.673615 | CL9: 52.676758 | CM9: 393.0274 | CN9: 161.84087 | CO9: 103.21259 | CP9: 126.18707 | CQ9: 0 | CR9: 72.493851 | CS9: 15.524586 | CT9: 57.203693 | CU9: 288.45197 | CV9: 120.71945 | CW9: 3 | CX9: 507 | CY9: 240.05615 | CZ9: 71.187126 | DA9: 29.70717 | DB9: 51.24548 | DC9: 96.888046 | DD9: 161 | DE9: 194 | DF9: 137.04555 | DG9: 114.96453 | DH9: 92.911255 | DI9: 48.785744 | DJ9: 263 | DK9: 154.97099 | DL9: 31.780001 | DM9: 63.617001 | DN9: 57.431999 | DO9: 121.62639 | DP9: 17.896999 | DR9: 67 | DS9: 52.700001 | DT9: 13 | DV9: 174 | DW9: 164.75746 | DX9: 13 | DZ9: 56 | EA9: 3 | EB9: 0 | EC9: 1 | ED9: 368 | EE9: 15.607 | EF9: 15.814167 | EG9: 16.758617 | EH9: 별도봉5
A10: =A9 + TIME(,1,) -> 46020.004 | B10: 321 | C10: 60.733002 | D10: 103.37 | E10: 24.881001 | F10: 5.7513156 | G10: 24.089001 | H10: 368 | I10: 331 | J10: 76.905998 | K10: 64.950317 | L10: 52.837002 | M10: 15.494 | N10: 16.031 | O10: 24 | P10: 0 | Q10: 24.789429 | R10: 30 | S10: 30.683126 | T10: 9 | U10: 9 | V10: 1270 | W10: 41.168247 | X10: 41.279999 | Y10: 11.133 | Z10: 0 | AA10: 32.458 | AB10: 0 | AC10: 70.701866 | AD10: 5.8520002 | AE10: 1.3725766 | AF10: 98.42366 | AG10: 0 | AH10: 99.78611 | AI10: 23.92 | AJ10: 44.108494 | AK10: 55.607811 | AL10: 63.792999 | AM10: 61.453999 | AN10: 170.875 | AO10: 96 | AP10: 92.685463 | AQ10: 62.307007 | AR10: 137 | AT10: 119 | AV10: 90 | AX10: 38 | AY10: 40.148674 | AZ10: 29 | BB10: 211 | BC10: 216.78099 | BD10: 7.5 | BE10: 7.5768986 | BF10: 31 | BG10: 13 | BH10: 13.347232 | BJ10: =SUM(BK10:BL10) -> 20 | BK10: 20 | BL10: 0 | BN10: =SUM(BO10:BP10) -> 125 | BO10: 76 | BP10: 49 | BQ10: 351 | BR10: 111.853 | BS10: 29.518 | BT10: 53.685001 | BU10: 52.419998 | BV10: 68.400002 | BW10: 7.5 | BX10: 13.9 | BY10: 28 | BZ10: 0.0134319 | CA10: 1 | CB10: 29.329826 | CD10: 420.99808 | CE10: 59.721844 | CF10: 34.574623 | CG10: 35.338192 | CH10: 304.04153 | CI10: 127.39327 | CJ10: 65.427933 | CK10: 67.892746 | CL10: 52.22855 | CM10: 406.91769 | CN10: 169.10246 | CO10: 104.16585 | CP10: 129.98943 | CQ10: 0 | CR10: 74.385391 | CS10: 14.609812 | CT10: 64.102631 | CU10: 288.98605 | CV10: 122.4894 | CW10: 3 | CX10: 507 | CY10: 239.44365 | CZ10: 70.504898 | DA10: 32.220268 | DB10: 51.900852 | DC10: 99.340919 | DD10: 171 | DE10: 192 | DF10: 138.92027 | DG10: 114.64311 | DH10: 92.662636 | DI10: 51.41016 | DJ10: 270 | DK10: 163.114 | DL10: 34.154999 | DM10: 70.154999 | DN10: 56.370998 | DO10: 118.00307 | DP10: 17.388 | DR10: 67 | DS10: 52.799999 | DT10: 14 | DV10: 174 | DW10: 164.47968 | DX10: 13 | DZ10: 54 | EA10: 3 | EB10: 0 | EC10: 1 | ED10: 373.89999 | EE10: 297 | EF10: 299.5 | EG10: 304.58333 | EH10: 건입저지대2
A11: =A10 + TIME(,1,) -> 46020.005 | B11: 332 | C11: 58.923 | D11: 104.049 | E11: 24.655001 | F11: 14.963305 | G11: 25.333 | H11: 360 | I11: 325 | J11: 78.037003 | K11: 65.589867 | L11: 51.599998 | M11: 15.268 | N11: 17.113001 | O11: 23 | P11: 0 | Q11: 23.958628 | R11: 28.003124 | S11: 30.683126 | T11: 9 | U11: 9 | V11: 1248 | W11: 41.847122 | X11: 41.618999 | Y11: 10.496 | Z11: 0 | AA11: 32.571999 | AB11: 0 | AC11: 66.565399 | AD11: 6.1069999 | AE11: 1.327227 | AF11: 95.642075 | AG11: 0 | AH11: 95.377983 | AI11: 24.047001 | AJ11: 44.159409 | AK11: 55.267872 | AL11: 62.733002 | AM11: 59.926998 | AN11: 172.3125 | AO11: 95 | AP11: 91.843727 | AQ11: 60.080677 | AR11: 135 | AT11: 119 | AV11: 89 | AX11: 37 | AY11: 39.941162 | AZ11: 29 | BB11: 209 | BC11: 216.11952 | BD11: 7.6999998 | BE11: 7.8914075 | BF11: 31 | BG11: 13 | BH11: 13.598321 | BJ11: =SUM(BK11:BL11) -> 21 | BK11: 21 | BL11: 0 | BN11: =SUM(BO11:BP11) -> 125 | BO11: 76 | BP11: 49 | BQ11: 357 | BR11: 114.002 | BS11: 28.5 | BT11: 57.148998 | BU11: 51.720001 | BV11: 69.300003 | BW11: 7.5 | BX11: 14.1 | BY11: 27 | BZ11: 0.014128822 | CA11: 0 | CB11: 29.375889 | CD11: 425.3497 | CE11: 60.641777 | CF11: 34.574623 | CG11: 35.338192 | CH11: 303.6593 | CI11: 128.29709 | CJ11: 64.125549 | CK11: 69.38018 | CL11: 52.624302 | CM11: 407.04749 | CN11: 167.79761 | CO11: 104.11352 | CP11: 131.11404 | CQ11: 0 | CR11: 74.686455 | CS11: 14.369219 | CT11: 62.098324 | CU11: 292.1712 | CV11: 120.6958 | CW11: 4 | CX11: 512 | CY11: 235.48888 | CZ11: 66.72364 | DA11: 33.645782 | DB11: 52.439579 | DC11: 101.14481 | DD11: 157 | DE11: 193 | DF11: 140.59552 | DG11: 116.87066 | DH11: 92.992584 | DI11: 49.803177 | DJ11: 265 | DK11: 157.51601 | DL11: 35.060001 | DM11: 68.210999 | DN11: 56.902 | DO11: 117.64662 | DP11: 18.01 | DR11: 67 | DS11: 53.400002 | DT11: 14 | DV11: 174 | DW11: 164.69023 | DX11: 13 | DZ11: 54 | EA11: 3 | EB11: 0 | EC11: 1 | ED11: 374.60001 | EE11: 267 | EF11: 268 | EG11: 271.93333 | EH11: 건입저지대
A12: =A11 + TIME(,1,) -> 46020.006 | B12: 326 | C12: 61.185001 | D12: 103.936 | E12: 24.881001 | F12: 10.350936 | G12: 24.315001 | H12: 362 | I12: 330 | J12: 79.959 | K12: 64.741936 | L12: 51.423 | M12: 16.059 | N12: 16.604 | O12: 22 | P12: 0 | Q12: 22.34712 | R12: 28.996876 | S12: 31.612785 | T12: 9 | U12: 9 | V12: 1249 | W12: 40.427906 | X12: 41.618999 | Y12: 11.133 | Z12: 0 | AA12: 37.548 | AB12: 0 | AC12: 68.553589 | AD12: 5.8520002 | AE12: 0 | AF12: 97.076309 | AG12: 0 | AH12: 89.950867 | AI12: 26.209999 | AJ12: 44.573734 | AK12: 54.406334 | AL12: 63.087002 | AM12: 61.327 | AN12: 169.4375 | AO12: 94 | AP12: 91.389816 | AQ12: 58.544582 | AR12: 135 | AT12: 119 | AV12: 90 | AX12: 38 | AY12: 40.272961 | AZ12: 29 | BB12: 210 | BC12: 216.11952 | BD12: 7.5 | BE12: 7.5568614 | BF12: 31 | BG12: 13 | BH12: 13.298993 | BJ12: =SUM(BK12:BL12) -> 21 | BK12: 21 | BL12: 0 | BN12: =SUM(BO12:BP12) -> 125 | BO12: 76 | BP12: 49 | BQ12: 357 | BR12: 116.037 | BS12: 29.009001 | BT12: 55.764 | BU12: 52.674999 | BV12: 69.5 | BW12: 7.3000002 | BX12: 13.6 | BY12: 29 | BZ12: 0.015137713 | CA12: 0 | CB12: 29.662889 | CD12: 419.99454 | CE12: 61.044838 | CF12: 34.260357 | CG12: 35.338192 | CH12: 303.5477 | CI12: 121.41271 | CJ12: 61.89143 | CK12: 65.515106 | CL12: 52.657738 | CM12: 398.90045 | CN12: 162.12227 | CO12: 106.6011 | CP12: 126.80576 | CQ12: 0 | CR12: 78.407692 | CS12: 13.810763 | CT12: 60.948204 | CU12: 288.45599 | CV12: 121.03718 | CW12: 5 | CX12: 513 | CY12: 234.96375 | CZ12: 69.156593 | DA12: 33.180958 | DB12: 51.972725 | DC12: 100.68467 | DD12: 173 | DE12: 192 | DF12: 138.71048 | DG12: 116.08127 | DH12: 93.543076 | DI12: 49.843372 | DJ12: 259 | DK12: 153.19 | DL12: 34.946999 | DM12: 63.263 | DN12: 57.431999 | DO12: 120.76661 | DP12: 18.320999 | DR12: 67 | DS12: 55.900002 | DT12: 14 | DV12: 178 | DW12: 165.30469 | DX12: 14 | DZ12: 53 | EA12: 3 | EB12: 0 | EC12: 1 | ED12: 375.89999 | EE12: 56.209 | EF12: 57.980667 | EG12: 60.44625 | EH12: 사라봉1
A13: =A12 + TIME(,1,) -> 46020.006 | B13: 326 | C13: 57.904999 | D13: 105.859 | E13: 22.280001 | F13: 2.2414823 | G13: 23.184 | H13: 363 | I13: 328 | J13: 77.696999 | K13: 64.214134 | L13: 52.130001 | M13: 16.625 | N13: 18.066999 | O13: 20 | P13: 0 | Q13: 21.416756 | R13: 30 | S13: 31.624062 | T13: 9 | U13: 9 | V13: 1256 | W13: 39.085224 | X13: 42.298 | Y13: 10.624 | Z13: 0 | AA13: 36.417 | AB13: 0 | AC13: 69.752136 | AD13: 5.8520002 | AE13: 1.370573 | AF13: 98.762848 | AG13: 0 | AH13: 88.622253 | AI13: 26.846001 | AJ13: 41.056042 | AK13: 54.113976 | AL13: 60.436001 | AM13: 58.654999 | AN13: 174.4375 | AO13: 96 | AP13: 91.580162 | AQ13: 60.802307 | AR13: 99 | AT13: 115 | AV13: 96 | AX13: 36 | AY13: 38.364235 | AZ13: 30 | BB13: 207 | BC13: 212.29175 | BD13: 7.5 | BE13: 7.5568614 | BF13: 31 | BG13: 13 | BH13: 13.246702 | BJ13: =SUM(BK13:BL13) -> 21 | BK13: 21 | BL13: 0 | BN13: =SUM(BO13:BP13) -> 125.2 | BO13: 76 | BP13: 49.200001 | BQ13: 357 | BR13: 114.341 | BS13: 30.535999 | BT13: 56.110001 | BU13: 50.893002 | BV13: 68.699997 | BW13: 7.5 | BX13: 13.9 | BY13: 30 | BZ13: 0.01507114 | CA13: 0 | CB13: 30.236523 | CD13: 420.48929 | CE13: 61.994293 | CF13: 34.188934 | CG13: 35.338192 | CH13: 304.26901 | CI13: 121.33688 | CJ13: 64.033737 | CK13: 63.88028 | CL13: 52.718994 | CM13: 392.14319 | CN13: 160.30719 | CO13: 105.31651 | CP13: 123.9566 | CQ13: 0 | CR13: 77.632912 | CS13: 14.198801 | CT13: 57.481743 | CU13: 290.15942 | CV13: 123.14513 | CW13: 3 | CX13: 511 | CY13: 235.64226 | CZ13: 69.467346 | DA13: 33.007183 | DB13: 51.136791 | DC13: 100.94879 | DD13: 171 | DE13: 193 | DF13: 136.67502 | DG13: 114.46614 | DH13: 94.153488 | DI13: 50.985859 | DJ13: 264 | DK13: 153.19 | DL13: 34.946999 | DM13: 62.202999 | DN13: 57.431999 | DO13: 119.83234 | DP13: 18.236 | DR13: 67 | DS13: 54.299999 | DT13: 14 | DV13: 182 | DW13: 164.88484 | DX13: 12 | DZ13: 54 | EA13: 3 | EB13: 0 | EC13: 1 | ED13: 373 | EE13: 59.093945 | EF13: 59.487239 | EG13: 60.400438 | EH13: 사라봉2
A14: =A13 + TIME(,1,) -> 46020.007 | B14: 318 | C14: 56.435001 | D14: 104.501 | E14: 20.469999 | F14: 8.2730141 | G14: 23.636999 | H14: 358 | I14: 328 | J14: 78.263 | K14: 64.172523 | L14: 51.423 | M14: 16.172001 | N14: 16.349001 | O14: 21 | P14: 0 | Q14: 21.416756 | R14: 28.996876 | S14: 30.912724 | T14: 9 | U14: 9 | V14: 1255 | W14: 39.664909 | X14: 41.506001 | Y14: 11.514 | Z14: 0 | AA14: 34.833 | AB14: 0 | AC14: 70.133133 | AD14: 6.1069999 | AE14: 0 | AF14: 98.762848 | AG14: 0 | AH14: 90.468201 | AI14: 22.266001 | AJ14: 46.131699 | AK14: 56.07312 | AL14: 65.029999 | AM14: 58.654999 | AN14: 173.625 | AO14: 97 | AP14: 91.001228 | AQ14: 62.588943 | AR14: 93 | AT14: 115 | AV14: 97 | AX14: 36 | AY14: 39.80632 | AZ14: 30 | BB14: 206 | BC14: 212.08411 | BD14: 7.5 | BE14: 7.5499668 | BF14: 31 | BG14: 13 | BH14: 13.268639 | BJ14: =SUM(BK14:BL14) -> 20 | BK14: 20 | BL14: 0 | BN14: =SUM(BO14:BP14) -> 124 | BO14: 75 | BP14: 49 | BQ14: 355 | BR14: 110.383 | BS14: 30.790001 | BT14: 56.110001 | BU14: 51.210999 | BV14: 69.400002 | BW14: 7.5999999 | BX14: 13.6 | BY14: 29 | BZ14: 0.014636578 | CA14: 0 | CB14: 30.371624 | CD14: 425.01096 | CE14: 59.860863 | CF14: 34.865379 | CG14: 35.338192 | CH14: 303.96896 | CI14: 124.39966 | CJ14: 62.438313 | CK14: 67.224823 | CL14: 52.718994 | CM14: 392.14319 | CN14: 160.30719 | CO14: 106.18343 | CP14: 126.38774 | CQ14: 0 | CR14: 75.74369 | CS14: 14.779314 | CT14: 55.766014 | CU14: 290.11139 | CV14: 123.42736 | CW14: 3 | CX14: 509 | CY14: 238.31346 | CZ14: 70.23246 | DA14: 35.188873 | DB14: 49.18684 | DC14: 100.90751 | DD14: 159 | DE14: 191 | DF14: 137.28389 | DG14: 115.16729 | DH14: 92.059624 | DI14: 48.399841 | DJ14: 261 | DK14: 152.172 | DL14: 32.685001 | DM14: 62.202999 | DN14: 56.902 | DO14: 122.20478 | DP14: 17.671 | DR14: 67 | DS14: 55.200001 | DT14: 13 | DV14: 179 | DW14: 164.99092 | DX14: 12 | DZ14: 55 | EA14: 3 | EB14: 0 | EC14: 1 | ED14: 371 | EE14: 40.820999 | EF14: 41.910499 | EG14: 43.447734 | EH14: 사라봉3
A15: =A14 + TIME(,1,) -> 46020.008 | B15: 319 | C15: 54.398998 | D15: 104.501 | E15: 21.375 | F15: 5.0308638 | G15: 23.070999 | H15: 362 | I15: 327 | J15: 77.471001 | K15: 64.046379 | L15: 52.66 | M15: 16.511999 | N15: 17.367001 | O15: 21 | P15: 0 | Q15: 20.870188 | R15: 28.996876 | S15: 30.317102 | T15: 9 | U15: 9 | V15: 1244 | W15: 39.06728 | X15: 41.618999 | Y15: 11.069 | Z15: 0 | AA15: 35.964001 | AB15: 0 | AC15: 69.891815 | AD15: 6.1069999 | AE15: 0 | AF15: 98.777283 | AG15: 0 | AH15: 92.53299 | AI15: 24.047001 | AJ15: 44.611923 | AK15: 55.517445 | AL15: 62.733002 | AM15: 58.146 | AN15: 171.5625 | AO15: 95 | AP15: 91.63871 | AQ15: 59.732323 | AR15: 92 | AT15: 115 | AV15: 97 | AX15: 39 | AY15: 39.80632 | AZ15: 30 | BB15: 208 | BC15: 213.39624 | BD15: 7.5 | BE15: 7.53861 | BF15: 30 | BG15: 13 | BH15: 13.232292 | BJ15: =SUM(BK15:BL15) -> 20 | BK15: 20 | BL15: 0 | BN15: =SUM(BO15:BP15) -> 124 | BO15: 75 | BP15: 49 | BQ15: 352 | BR15: 110.722 | BS15: 32.317001 | BT15: 54.377998 | BU15: 52.419998 | BV15: 69.599998 | BW15: 7.5 | BX15: 13.8 | BY15: 30 | BZ15: 0.014893939 | CA15: 1 | CB15: 30.535364 | CD15: 425.03387 | CE15: 60.518856 | CF15: 34.899822 | CG15: 35.338192 | CH15: 303.70825 | CI15: 119.69819 | CJ15: 60.17432 | CK15: 66.060837 | CL15: 54.005825 | CM15: 386.35193 | CN15: 155.06874 | CO15: 104.17142 | CP15: 126.20232 | CQ15: 0 | CR15: 74.715088 | CS15: 13.938737 | CT15: 58.511089 | CU15: 291.08664 | CV15: 121.84751 | CW15: 4 | CX15: 505 | CY15: 236.67189 | CZ15: 67.669151 | DA15: 34.984074 | DB15: 46.571823 | DC15: 102.00808 | DD15: 166 | DE15: 191 | DF15: 138.82065 | DG15: 116.83268 | DH15: 91.247223 | DI15: 48.488289 | DJ15: 264 | DK15: 153.953 | DL15: 29.405001 | DM15: 62.733002 | DN15: 57.431999 | DO15: 123.86529 | DP15: 16.455 | DR15: 67 | DS15: 53.700001 | DT15: 13 | DV15: 179 | DW15: 165.54102 | DX15: 14 | DZ15: 55 | EA15: 3 | EB15: 0 | EC15: 1 | ED15: 369.5 | EE15: 10.97 | EF15: 11.309 | EG15: 11.833283 | EH15: 사라봉4
A16: =A15 + TIME(,1,) -> 46020.008 | B16: 319 | C16: 58.696999 | D16: 104.388 | E16: 19.565001 | F16: 5.0308638 | G16: 23.524 | H16: 364 | I16: 324 | J16: 77.584 | K16: 63.217766 | L16: 52.484001 | M16: 17.416 | N16: 16.667 | O16: 22 | P16: 0 | Q16: 21.427013 | R16: 30 | S16: 31.24642 | T16: 9 | U16: 9 | V16: 1246 | W16: 39.74482 | X16: 41.846001 | Y16: 10.687 | Z16: 0 | AA16: 35.512001 | AB16: 0 | AC16: 68.912254 | AD16: 6.1069999 | AE16: 0 | AF16: 100.48977 | AG16: 0 | AH16: 90.499008 | AI16: 24.809999 | AJ16: 40.388863 | AK16: 53.384731 | AL16: 60.436001 | AM16: 62.598999 | AN16: 173 | AO16: 95 | AP16: 90.188431 | AQ16: 60.22715 | AR16: 93 | AT16: 115 | AV16: 94 | AX16: 37 | AY16: 39.042645 | AZ16: 30 | BB16: 207 | BC16: 212.79041 | BD16: 7.5 | BE16: 7.5353889 | BF16: 30 | BG16: 13 | BH16: 13.139482 | BJ16: =SUM(BK16:BL16) -> 20 | BK16: 20 | BL16: 0 | BN16: =SUM(BO16:BP16) -> 125 | BO16: 76 | BP16: 49 | BQ16: 352 | BR16: 106.99 | BS16: 29.518 | BT16: 56.456001 | BU16: 50.893002 | BV16: 69.400002 | BW16: 7.3000002 | BX16: 13.9 | BY16: 30 | BZ16: 0.013830421 | CA16: 0 | CB16: 30.459751 | CD16: 422.64224 | CE16: 58.876827 | CF16: 34.787712 | CG16: 35.338192 | CH16: 303.10162 | CI16: 117.22688 | CJ16: 56.0532 | CK16: 66.672089 | CL16: 51.418678 | CM16: 387.02423 | CN16: 155.06874 | CO16: 103.42792 | CP16: 125.13323 | CQ16: 0 | CR16: 71.760666 | CS16: 16.834255 | CT16: 58.269657 | CU16: 292.13681 | CV16: 125.74982 | CW16: 5 | CX16: 505 | CY16: 234.54832 | CZ16: 67.710289 | DA16: 31.673512 | DB16: 49.846649 | DC16: 103.45866 | DD16: 165 | DE16: 191 | DF16: 138.51878 | DG16: 116.83268 | DH16: 76.351631 | DI16: 49.513901 | DJ16: 267 | DK16: 154.717 | DL16: 32.118999 | DM16: 66.444 | DN16: 57.785 | DO16: 119.97417 | DP16: 16.936001 | DR16: 67 | DS16: 53.099998 | DT16: 14 | DV16: 179 | DW16: 164.75247 | DX16: 13 | DZ16: 56 | EA16: 3 | EB16: 0 | EC16: 1 | ED16: 358.5 | EE16: 15.713 | EF16: 16.031 | EG16: 17.025584 | EH16: 사라봉5
... A46: =A45 + TIME(,1,) -> 46020.029 | B46: 301 | C46: 58.923 | D46: 103.031 | E46: 21.035999 | F46: 13.880548 | G46: 22.052999 | H46: 365 | I46: 327 | J46: 74.078003 | K46: 64.739708 | L46: 52.484001 | M46: 14.702 | N46: 17.302999 | O46: 19 | P46: 0 | Q46: 20.227598 | R46: 28.003124 | S46: 28.30788 | T46: 0 | U46: 0 | V46: 1186 | W46: 37.561768 | X46: 37.887001 | Y46: 9.8599997 | Z46: 0 | AA46: 35.512001 | AB46: 0 | AC46: 62.800201 | AD46: 6.1069999 | AE46: 0 | AF46: 96.540886 | AG46: 0 | AH46: 80.843681 | AI46: 18.320999 | AJ46: 29.633221 | AK46: 52.353458 | AL46: 60.436001 | AM46: 58.400002 | AN46: 153.375 | AO46: 86 | AP46: 81.901833 | AQ46: 52.822979 | AR46: 132 | AT46: 121 | AV46: 95 | AX46: 34 | AY46: 36.668953 | AZ46: 26 | BB46: 194 | BC46: 200.18515 | BD46: 7.3000002 | BE46: 7.3289733 | BF46: 31 | BG46: 12 | BH46: 12.275046 | BJ46: =SUM(BK46:BL46) -> 17 | BK46: 17 | BL46: 0 | BN46: =SUM(BO46:BP46) -> 123 | BO46: 75 | BP46: 48 | BQ46: 326 | BR46: 96.472 | BS46: 25.955 | BT46: 50.915001 | BU46: 46.375999 | BV46: 69.099998 | BW46: 7.0999999 | BX46: 13.9 | BY46: 29 | BZ46: 0.015184899 | CA46: 0 | CB46: 29.312881 | CD46: 444.80963 | CE46: 89.391449 | CF46: 32.65873 | CG46: 35.338192 | CH46: 303.78659 | CI46: 117.32188 | CJ46: 58.164085 | CK46: 61.381073 | CL46: 48.56813 | CM46: 334.44867 | CN46: 134.51205 | CO46: 91.486961 | CP46: 103.97105 | CQ46: 0 | CR46: 66.308044 | CS46: 11.696434 | CT46: 50.284843 | CU46: 180.03578 | CV46: 91.127495 | CW46: 2 | CX46: 464 | CY46: 219.41118 | CZ46: 65.285515 | DA46: 22.256344 | DB46: 44.946106 | DC46: 91.136261 | DD46: 677 | DE46: 202 | DF46: 702.01349 | DG46: 97.885788 | DH46: 66.405075 | DI46: 44.536415 | DJ46: 255 | DK46: 151.15401 | DL46: 28.726 | DM46: 61.319 | DN46: 54.074001 | DO46: 115.22613 | DP46: 17.275 | DR46: 67 | DS46: 48.5 | DT46: 13 | DV46: 174 | DW46: 165.43083 | DX46: 12 | DZ46: 52 | EA46: 3 | EB46: 0 | EC46: 1 | ED46: 852.70001 | EE46: 78 | EF46: 79.833333 | EG46: 83.883333 | EH46: 산천단배법원유출
A47: =A46 + TIME(,1,) -> 46020.03 | B47: 300 | C47: 60.167 | D47: 102.239 | E47: 19.452 | F47: 4.7167068 | G47: 21.827 | H47: 360 | I47: 326 | J47: 74.078003 | K47: 64.609306 | L47: 52.484001 | M47: 14.815 | N47: 17.302999 | O47: 19 | P47: 0 | Q47: 19.242571 | R47: 25.003124 | S47: 25.552282 | T47: 0 | U47: 0 | V47: 1180 | W47: 37.293118 | X47: 36.417 | Y47: 10.496 | Z47: 0 | AA47: 34.720001 | AB47: 0 | AC47: 64.167801 | AD47: 6.1069999 | AE47: 0 | AF47: 99.185699 | AG47: 0 | AH47: 79.067924 | AI47: 17.812 | AJ47: 30.387894 | AK47: 51.663074 | AL47: 58.492001 | AM47: 57.700001 | AN47: 152.6875 | AO47: 83 | AP47: 82.847076 | AQ47: 51.959026 | AR47: 131 | AT47: 121 | AV47: 102 | AX47: 35 | AY47: 37.314304 | AZ47: 26 | BB47: 196 | BC47: 201.7475 | BD47: 7.3000002 | BE47: 7.3289733 | BF47: 31 | BG47: 12 | BH47: 12.375345 | BJ47: =SUM(BK47:BL47) -> 17 | BK47: 17 | BL47: 0 | BN47: =SUM(BO47:BP47) -> 123.2 | BO47: 75 | BP47: 48.200001 | BQ47: 317 | BR47: 98.959999 | BS47: 26.973 | BT47: 48.835999 | BU47: 46.249001 | BV47: 69.400002 | BW47: 6.9000001 | BX47: 13.9 | BY47: 28 | BZ47: 0.013904979 | CA47: 0 | CB47: 29.321377 | CD47: 448.46976 | CE47: 87.893379 | CF47: 31.893793 | CG47: 35.338192 | CH47: 302.89377 | CI47: 116.13103 | CJ47: 57.728199 | CK47: 60.259232 | CL47: 46.980465 | CM47: 330.57175 | CN47: 134.51205 | CO47: 92.014343 | CP47: 99.344467 | CQ47: 0 | CR47: 65.183517 | CS47: 11.86727 | CT47: 52.92952 | CU47: 182.97507 | CV47: 89.691788 | CW47: 2 | CX47: 464 | CY47: 222.71654 | CZ47: 67.357117 | DA47: 23.003315 | DB47: 42.372879 | DC47: 92.729767 | DD47: 677 | DE47: 202 | DF47: 704.92944 | DG47: 104.53021 | DH47: 66.553421 | DI47: 41.476204 | DJ47: 255 | DK47: 151.15401 | DL47: 28.726 | DM47: 62.202999 | DN47: 55.487999 | DO47: 118.83825 | DP47: 17.275 | DR47: 67 | DS47: 55.099998 | DT47: 13 | DV47: 176 | DW47: 165.01073 | DX47: 12 | DZ47: 52 | EA47: 3 | EB47: 0 | EC47: 1 | ED47: 857.40002 | EE47: 0 | EF47: #NUM! | EG47: #DIV/0! | EH47: 산천단1_1
A48: =A47 + TIME(,1,) -> 46020.031 | B48: 290 | C48: 58.358002 | D48: 102.466 | E48: 19.677999 | F48: 4.4994135 | G48: 21.714001 | H48: 361 | I48: 328 | J48: 76.226997 | K48: 65.214546 | L48: 52.130001 | M48: 15.155 | N48: 16.922001 | O48: 20 | P48: 0 | Q48: 18.510984 | R48: 24 | S48: 24.828302 | T48: 0 | U48: 0 | V48: 1185 | W48: 34.035061 | X48: 36.756001 | Y48: 8.4610004 | Z48: 0 | AA48: 32.231998 | AB48: 0 | AC48: 63.187622 | AD48: 6.1069999 | AE48: 0 | AF48: 99.078438 | AG48: 0 | AH48: 78.329308 | AI48: 19.657 | AJ48: 31.744631 | AK48: 52.046444 | AL48: 60.082001 | AM48: 58.337002 | AN48: 158.5 | AO48: 86 | AP48: 82.859688 | AQ48: 52.705051 | AR48: 129 | AT48: 121 | AV48: 102 | AX48: 34 | AY48: 36.999207 | AZ48: 26 | BB48: 195 | BC48: 202.40591 | BD48: 7.4000001 | BE48: 7.3687439 | BF48: 31 | BG48: 12 | BH48: 12.223081 | BJ48: =SUM(BK48:BL48) -> 17 | BK48: 17 | BL48: 0 | BN48: =SUM(BO48:BP48) -> 122.2 | BO48: 74 | BP48: 48.200001 | BQ48: 317 | BR48: 99.750999 | BS48: 26.719 | BT48: 48.835999 | BU48: 46.057999 | BV48: 69.599998 | BW48: 6.9000001 | BX48: 14 | BY48: 28 | BZ48: 0.013904979 | CA48: 1 | CB48: 29.324104 | CD48: 447.03223 | CE48: 87.035065 | CF48: 32.170959 | CG48: 35.338192 | CH48: 303.00418 | CI48: 117.40604 | CJ48: 58.59079 | CK48: 60.259232 | CL48: 46.133274 | CM48: 330.61646 | CN48: 134.82645 | CO48: 90.869522 | CP48: 100.04868 | CQ48: 0 | CR48: 67.300339 | CS48: 11.226767 | CT48: 52.295189 | CU48: 183.30388 | CV48: 92.559174 | CW48: 3 | CX48: 466 | CY48: 220.68597 | CZ48: 65.619553 | DA48: 23.876944 | DB48: 43.217392 | DC48: 91.459999 | DD48: 674 | DE48: 201 | DF48: 705.12042 | DG48: 102.28314 | DH48: 66.769852 | DI48: 41.185894 | DJ48: 254 | DK48: 145.30099 | DL48: 28.5 | DM48: 60.258999 | DN48: 56.724998 | DO48: 115.7267 | DP48: 17.445 | DR48: 67 | DS48: 55.900002 | DT48: 14 | DV48: 176 | DW48: 165.01073 | DX48: 12 | DZ48: 52 | EA48: 3 | EB48: 0 | EC48: 1 | ED48: 851.90002 | EE48: 91 | EF48: 92.333333 | EG48: 95.916667 | EH48: 산천단배제대유출
A49: =A48 + TIME(,1,) -> 46020.031 | B49: 302 | C49: 54.852001 | D49: 103.936 | E49: 22.393 | F49: 12.485354 | G49: 21.827 | H49: 359 | I49: 322 | J49: 76.905998 | K49: 65.032112 | L49: 51.07 | M49: 14.589 | N49: 17.049 | O49: 20 | P49: 0 | Q49: 20.069675 | R49: 25.003124 | S49: 25.22114 | T49: 0 | U49: 0 | V49: 1189 | W49: 35.367905 | X49: 35.173 | Y49: 8.9700003 | Z49: 0 | AA49: 30.535999 | AB49: 0 | AC49: 64.22802 | AD49: 6.1069999 | AE49: 0 | AF49: 98.717239 | AG49: 0 | AH49: 76.205765 | AI49: 17.621 | AJ49: 31.560925 | AK49: 53.151855 | AL49: 61.143002 | AM49: 57.637001 | AN49: 160.9375 | AO49: 86 | AP49: 83.698128 | AQ49: 52.721882 | AR49: 130 | AT49: 121 | AV49: 103 | AX49: 35 | AY49: 36.779419 | AZ49: 26 | BB49: 197 | BC49: 203.72897 | BD49: 7.4000001 | BE49: 7.356916 | BF49: 30 | BG49: 11 | BH49: 12.189432 | BJ49: =SUM(BK49:BL49) -> 17 | BK49: 17 | BL49: 0 | BN49: =SUM(BO49:BP49) -> 122.2 | BO49: 74 | BP49: 48.200001 | BQ49: 320 | BR49: 99.185997 | BS49: 27.228001 | BT49: 47.105 | BU49: 45.740002 | BV49: 70 | BW49: 7 | BX49: 13.9 | BY49: 30 | BZ49: 0.013866311 | CA49: 0 | CB49: 29.830925 | CD49: 444.91962 | CE49: 85.632652 | CF49: 31.712088 | CG49: 35.338192 | CH49: 303.64444 | CI49: 115.85818 | CJ49: 57.39114 | CK49: 60.677952 | CL49: 46.823986 | CM49: 329.35052 | CN49: 134.5892 | CO49: 90.743568 | CP49: 100.37511 | CQ49: 0 | CR49: 63.55014 | CS49: 12.033356 | CT49: 57.332634 | CU49: 184.95601 | CV49: 94.912003 | CW49: 8 | CX49: 454 | CY49: 218.03008 | CZ49: 61.325226 | DA49: 23.730526 | DB49: 41.835133 | DC49: 91.128014 | DD49: 675 | DE49: 203 | DF49: 705.77795 | DG49: 102.04482 | DH49: 66.417732 | DI49: 41.870739 | DJ49: 249 | DK49: 144.79201 | DL49: 30.083 | DM49: 59.199001 | DN49: 56.724998 | DO49: 115.14017 | DP49: 17.530001 | DR49: 67 | DS49: 54.700001 | DT49: 13 | DV49: 175 | DW49: 165.47984 | DX49: 11 | DZ49: 55 | EA49: 3 | EB49: 0 | EC49: 1 | ED49: 855.5 | EE49: 0 | EF49: #NUM! | EG49: #DIV/0! | EH49: 산천단1_2
A50: =A49 + TIME(,1,) -> 46020.032 | B50: 291 | C50: 52.25 | D50: 103.823 | E50: 17.982 | F50: 10.602694 | G50: 22.052999 | H50: 359 | I50: 322 | J50: 73.287003 | K50: 65.100945 | L50: 51.07 | M50: 14.815 | N50: 17.431 | O50: 18 | P50: 0 | Q50: 18.72488 | R50: 28.003124 | S50: 28.496367 | T50: 6 | U50: 6 | V50: 1173 | W50: 39.016899 | X50: 36.077999 | Y50: 8.5240002 | Z50: 0 | AA50: 32.798 | AB50: 0 | AC50: 64.573601 | AD50: 6.1069999 | AE50: 0 | AF50: 97.582855 | AG50: 0 | AH50: 75.1213 | AI50: 19.212 | AJ50: 31.111219 | AK50: 51.928974 | AL50: 58.668999 | AM50: 57.637001 | AN50: 159.8125 | AO50: 84 | AP50: 83.676132 | AQ50: 53.954845 | AR50: 129 | AT50: 121 | AV50: 103 | AX50: 35 | AY50: 37.251442 | AZ50: 26 | BB50: 197 | BC50: 203.71927 | BD50: 7.4000001 | BE50: 7.3350396 | BF50: 30 | BG50: 11 | BH50: 12.219166 | BJ50: =SUM(BK50:BL50) -> 17 | BK50: 17 | BL50: 0 | BN50: =SUM(BO50:BP50) -> 124.2 | BO50: 76 | BP50: 48.200001 | BQ50: 320 | BR50: 97.263 | BS50: 27.228001 | BT50: 47.105 | BU50: 45.549 | BV50: 69 | BW50: 7.1999998 | BX50: 13.9 | BY50: 29 | BZ50: 0.013759936 | CA50: 0 | CB50: 29.492544 | CD50: 441.46588 | CE50: 87.335899 | CF50: 31.676218 | CG50: 35.338192 | CH50: 305.15982 | CI50: 110.85799 | CJ50: 53.476845 | CK50: 60.464798 | CL50: 47.887566 | CM50: 329.35052 | CN50: 132.97789 | CO50: 90.743568 | CP50: 98.753426 | CQ50: 0 | CR50: 62.797039 | CS50: 11.873849 | CT50: 55.661762 | CU50: 177.62036 | CV50: 93.047012 | CW50: 3 | CX50: 451 | CY50: 221.38248 | CZ50: 61.333908 | DA50: 23.356056 | DB50: 41.610722 | DC50: 91.893089 | DD50: 676 | DE50: 204 | DF50: 705.68457 | DG50: 98.355515 | DH50: 66.433983 | DI50: 41.811081 | DJ50: 249 | DK50: 146.065 | DL50: 31.327 | DM50: 59.199001 | DN50: 53.721001 | DO50: 114.97992 | DP50: 17.445 | DR50: 67 | DS50: 54.599998 | DT50: 13 | DV50: 174 | DW50: 164.82828 | DX50: 12 | DZ50: 54 | EA50: 3 | EB50: 0 | EC50: 2 | ED50: 851.20001 | EE50: 49 | EF50: 49.5 | EG50: 54.416667 | EH50: 산천단배첨단유출
A51: =A50 + TIME(,1,) -> 46020.033 | B51: 291 | C51: 55.304001 | D51: 103.71 | E51: 18.320999 | F51: 13.20858 | G51: 22.167 | H51: 358 | I51: 326 | J51: 75.209 | K51: 65.269897 | L51: 53.543999 | M51: 15.155 | N51: 16.731001 | O51: 19 | P51: 0 | Q51: 20.545189 | R51: 27 | S51: 27.180487 | T51: 9 | U51: 9 | V51: 1173 | W51: 39.368435 | X51: 37.887001 | Y51: 8.7150002 | Z51: 0 | AA51: 30.309999 | AB51: 0 | AC51: 62.973495 | AD51: 5.598 | AE51: 0 | AF51: 96.512505 | AG51: 0 | AH51: 76.825401 | AI51: 17.940001 | AJ51: 29.651268 | AK51: 51.911392 | AL51: 60.436001 | AM51: 57.637001 | AN51: 152.9375 | AO51: 83 | AP51: 82.636429 | AQ51: 51.130566 | AR51: 131 | AT51: 122 | AV51: 95 | AX51: 36 | AY51: 37.765263 | AZ51: 25 | BB51: 197 | BC51: 205.10597 | BD51: 7.3000002 | BE51: 7.333415 | BF51: 31 | BG51: 11 | BH51: 12.267275 | BJ51: =SUM(BK51:BL51) -> 17 | BK51: 17 | BL51: 0 | BN51: =SUM(BO51:BP51) -> 122 | BO51: 74 | BP51: 48 | BQ51: 328 | BR51: 98.620003 | BS51: 27.482 | BT51: 48.490002 | BU51: 46.122002 | BV51: 69.5 | BW51: 7.0999999 | BX51: 14.2 | BY51: 29 | BZ51: 0.013759936 | CA51: 0 | CB51: 29.452539 | CD51: 445.72183 | CE51: 87.457794 | CF51: 31.238403 | CG51: 35.338192 | CH51: 304.05655 | CI51: 109.41899 | CJ51: 53.591297 | CK51: 61.280415 | CL51: 46.48917 | CM51: 328.75919 | CN51: 133.91878 | CO51: 91.126228 | CP51: 99.862793 | CQ51: 0 | CR51: 64.764702 | CS51: 12.51735 | CT51: 55.857544 | CU51: 172.73978 | CV51: 93.774681 | CW51: 3 | CX51: 451 | CY51: 221.78256 | CZ51: 63.544952 | DA51: 23.580318 | DB51: 42.821678 | DC51: 92.079605 | DD51: 676 | DE51: 204 | DF51: 703.61456 | DG51: 97.881615 | DH51: 66.993095 | DI51: 41.011631 | DJ51: 251 | DK51: 148.60899 | DL51: 29.969999 | DM51: 64.323997 | DN51: 53.721001 | DO51: 116.85677 | DP51: 16.794001 | DR51: 67 | DS51: 54.900002 | DT51: 14 | DV51: 174 | DW51: 165.84393 | DX51: 13 | DZ51: 53 | EA51: 3 | EB51: 0 | EC51: 1 | ED51: 851 | EE51: 0 | EF51: #NUM! | EG51: #DIV/0! | EH51: 산천단2
A52: =A51 + TIME(,1,) -> 46020.033 | B52: 294 | C52: 54.285999 | D52: 102.353 | E52: 21.827 | F52: 18.3853 | G52: 22.618999 | H52: 362 | I52: 331 | J52: 75.775002 | K52: 64.954842 | L52: 51.247002 | M52: 15.041 | N52: 16.540001 | O52: 18 | P52: 0 | Q52: 17.982571 | R52: 27 | S52: 28.869337 | T52: 9 | U52: 9 | V52: 1173 | W52: 38.718807 | X52: 36.756001 | Y52: 8.9060001 | Z52: 0 | AA52: 29.969999 | AB52: 0 | AC52: 63.795105 | AD52: 6.1069999 | AE52: 0 | AF52: 96.680283 | AG52: 0 | AH52: 77.585831 | AI52: 19.148001 | AJ52: 30.545166 | AK52: 50.926762 | AL52: 57.962002 | AM52: 60.244999 | AN52: 152.9375 | AO52: 82 | AP52: 82.789848 | AQ52: 51.395123 | AR52: 131 | AT52: 122 | AV52: 95 | AX52: 34 | AY52: 37.69009 | AZ52: 25 | BB52: 196 | BC52: 202.37393 | BD52: 7.3000002 | BE52: 7.3284984 | BF52: 31 | BG52: 11 | BH52: 12.100984 | BJ52: =SUM(BK52:BL52) -> 17 | BK52: 17 | BL52: 0 | BN52: =SUM(BO52:BP52) -> 123 | BO52: 75 | BP52: 48 | BQ52: 324 | BR52: 98.620003 | BS52: 26.719 | BT52: 48.835999 | BU52: 45.931 | BV52: 68.800003 | BW52: 7 | BX52: 13.9 | BY52: 29 | BZ52: 0.014663056 | CA52: 0 | CB52: 29.4641 | CD52: 442.60004 | CE52: 88.192841 | CF52: 31.941841 | CG52: 35.338192 | CH52: 304.48163 | CI52: 114.56686 | CJ52: 56.292534 | CK52: 61.972137 | CL52: 46.936947 | CM52: 327.93863 | CN52: 133.39708 | CO52: 91.140213 | CP52: 99.273911 | CQ52: 0 | CR52: 64.047791 | CS52: 12.914511 | CT52: 57.55331 | CU52: 179.09154 | CV52: 92.509506 | CW52: 4 | CX52: 461 | CY52: 216.91249 | CZ52: 60.325459 | DA52: 22.8815 | DB52: 42.418648 | DC52: 92.320953 | DD52: 677 | DE52: 201 | DF52: 706.32849 | DG52: 97.515327 | DH52: 67.28215 | DI52: 39.55611 | DJ52: 253 | DK52: 151.15401 | DL52: 29.969999 | DM52: 62.733002 | DN52: 56.548 | DO52: 115.64682 | DP52: 16.597 | DR52: 67 | DS52: 56.5 | DT52: 14 | DV52: 169 | DW52: 164.32428 | DX52: 12 | DZ52: 53 | EA52: 3 | EB52: 0 | EC52: 1 | ED52: 851 | EE52: 28 | EF52: 28.5 | EG52: 29.483333 | EH52: 황세앗유출
A53: =A52 + TIME(,1,) -> 46020.034 | B53: 293 | C53: 55.304001 | D53: 103.144 | E53: 18.547001 | F53: 14.202644 | G53: 21.714001 | H53: 356 | I53: 326 | J53: 74.757004 | K53: 64.954842 | L53: 49.655998 | M53: 15.494 | N53: 17.493999 | O53: 20 | P53: 0 | Q53: 20.24267 | R53: 28.003124 | S53: 28.850794 | T53: 9 | U53: 9 | V53: 1184 | W53: 37.65591 | X53: 37.548 | Y53: 9.033 | Z53: 0 | AA53: 29.969999 | AB53: 0 | AC53: 63.859364 | AD53: 5.8520002 | AE53: 0 | AF53: 96.554924 | AG53: 0 | AH53: 77.207642 | AI53: 21.438999 | AJ53: 29.395048 | AK53: 50.109215 | AL53: 58.492001 | AM53: 58.400002 | AN53: 155.875 | AO53: 85 | AP53: 83.468338 | AQ53: 52.227459 | AR53: 130 | AT53: 123 | AV53: 96 | AX53: 35 | AY53: 36.878948 | AZ53: 26 | BB53: 198 | BC53: 204.08598 | BD53: 7.3000002 | BE53: 7.3243866 | BF53: 31 | BG53: 11 | BH53: 12.130974 | BJ53: =SUM(BK53:BL53) -> 17 | BK53: 17 | BL53: 0 | BN53: =SUM(BO53:BP53) -> 123 | BO53: 75 | BP53: 48 | BQ53: 322 | BR53: 100.656 | BS53: 27.228001 | BT53: 46.064999 | BU53: 45.994999 | BV53: 70.099998 | BW53: 6.9000001 | BX53: 13.9 | BY53: 29 | BZ53: 0.014163781 | CA53: 1 | CB53: 29.916246 | CD53: 440.97812 | CE53: 86.491455 | CF53: 31.613674 | CG53: 35.338192 | CH53: 304.22086 | CI53: 110.49915 | CJ53: 54.74218 | CK53: 60.788105 | CL53: 48.658543 | CM53: 323.52029 | CN53: 130.57173 | CO53: 90.353363 | CP53: 99.470978 | CQ53: 0 | CR53: 65.495819 | CS53: 11.656232 | CT53: 55.134678 | CU53: 178.27597 | CV53: 92.782578 | CW53: 1 | CX53: 453 | CY53: 213.61206 | CZ53: 61.758049 | DA53: 24.50613 | DB53: 43.461231 | DC53: 93.320229 | DD53: 679 | DE53: 201 | DF53: 707.44824 | DG53: 95.791527 | DH53: 67.467079 | DI53: 43.416569 | DJ53: 251 | DK53: 145.81 | DL53: 32.571999 | DM53: 62.556 | DN53: 54.074001 | DO53: 115.97617 | DP53: 17.021 | DR53: 67 | DS53: 56.299999 | DT53: 14 | DV53: 172 | DW53: 164.69351 | DX53: 13 | DZ53: 53 | EA53: 3 | EB53: 0 | EC53: 2 | ED53: 853.90002 | EE53: 31.437574 | EF53: 31.655987 | EG53: 32.389782 | EH53: 영평15
A54: =A53 + TIME(,1,) -> 46020.035 | B54: 290 | C54: 58.584 | D54: 102.239 | E54: 18.320999 | F54: 2.8119836 | G54: 21.714001 | H54: 360 | I54: 328 | J54: 74.078003 | K54: 63.717735 | L54: 50.362999 | M54: 15.381 | N54: 16.731001 | O54: 19 | P54: 0 | Q54: 18.818911 | R54: 27 | S54: 28.228323 | T54: 9 | U54: 9 | V54: 1163 | W54: 37.223888 | X54: 37.887001 | Y54: 9.9870005 | Z54: 0 | AA54: 27.030001 | AB54: 0 | AC54: 63.459305 | AD54: 6.1069999 | AE54: 0 | AF54: 95.837234 | AG54: 0 | AH54: 77.931068 | AI54: 19.403 | AJ54: 29.01119 | AK54: 51.128693 | AL54: 62.202999 | AM54: 57.700001 | AN54: 154 | AO54: 84 | AP54: 82.763184 | AQ54: 50.490597 | AR54: 131 | AT54: 123 | AV54: 93 | AX54: 36 | AY54: 37.805698 | AZ54: 26 | BB54: 196 | BC54: 202.37936 | BD54: 7.3000002 | BE54: 7.3207989 | BF54: 30 | BG54: 12 | BH54: 12.169749 | BJ54: =SUM(BK54:BL54) -> 17 | BK54: 17 | BL54: 0 | BN54: =SUM(BO54:BP54) -> 123 | BO54: 75 | BP54: 48 | BQ54: 325 | BR54: 96.810997 | BS54: 27.737 | BT54: 46.757999 | BU54: 45.931 | BV54: 69 | BW54: 6.9000001 | BX54: 13.9 | BY54: 29 | BZ54: 0.012568527 | CA54: 0 | CB54: 30.057493 | CD54: 438.18066 | CE54: 84.725769 | CF54: 30.722651 | CG54: 35.338192 | CH54: 303.7648 | CI54: 108.82846 | CJ54: 52.227909 | CK54: 60.207695 | CL54: 44.934929 | CM54: 326.14526 | CN54: 133.50195 | CO54: 91.255219 | CP54: 98.721863 | CQ54: 0 | CR54: 66.133102 | CS54: 11.789154 | CT54: 52.702663 | CU54: 174.44894 | CV54: 92.173897 | CW54: 4 | CX54: 461 | CY54: 216.07156 | CZ54: 61.98455 | DA54: 24.029774 | DB54: 43.26104 | DC54: 94.156166 | DD54: 681 | DE54: 203 | DF54: 705.66748 | DG54: 92.75518 | DH54: 69.182648 | DI54: 42.229229 | DJ54: 251 | DK54: 145.556 | DL54: 27.708 | DM54: 60.082001 | DN54: 53.896999 | DO54: 117.3966 | DP54: 17.021 | DR54: 67 | DS54: 56.599998 | DT54: 15 | DV54: 172 | DW54: 164.21237 | DX54: 12 | DZ54: 53 | EA54: 3 | EB54: 0 | EC54: 1 | ED54: 853.5 | EE54: 0 | EF54: 0.5 | EG54: 3.6833333 | EH54: 영평소배유출
A55: =A54 + TIME(,1,) -> 46020.035 | B55: 297 | C55: 52.25 | D55: 103.031 | E55: 17.530001 | F55: 2.8119836 | G55: 22.167 | H55: 351 | I55: 325 | J55: 72.946999 | K55: 64.801201 | L55: 49.303001 | M55: 14.589 | N55: 16.985001 | O55: 17 | P55: 0 | Q55: 17.576303 | R55: 28.003124 | S55: 28.822174 | T55: 9 | U55: 9 | V55: 1177 | W55: 37.151466 | X55: 38.452999 | Y55: 9.0970001 | Z55: 0 | AA55: 28.952 | AB55: 0 | AC55: 62.824436 | AD55: 6.1069999 | AE55: 0 | AF55: 95.182159 | AG55: 0 | AH55: 78.497047 | AI55: 20.039 | AJ55: 27.367483 | AK55: 51.161758 | AL55: 61.849998 | AM55: 57.637001 | AN55: 152.6875 | AO55: 84 | AP55: 83.547829 | AQ55: 50.950848 | AR55: 117 | AT55: 120 | AV55: 99 | AX55: 35 | AY55: 37.13707 | AZ55: 26 | BB55: 195 | BC55: 199.88339 | BD55: 7.3000002 | BE55: 7.320467 | BF55: 30 | BG55: 11 | BH55: 12.034399 | BJ55: =SUM(BK55:BL55) -> 17 | BK55: 17 | BL55: 0 | BN55: =SUM(BO55:BP55) -> 122 | BO55: 74 | BP55: 48 | BQ55: 317 | BR55: 96.924004 | BS55: 25.955 | BT55: 46.064999 | BU55: 45.676998 | BV55: 69.199997 | BW55: 6.9000001 | BX55: 13.6 | BY55: 29 | BZ55: 0.014959736 | CA55: 0 | CB55: 29.399513 | CD55: 437.64127 | CE55: 84.178085 | CF55: 30.722651 | CG55: 35.338192 | CH55: 303.80722 | CI55: 112.90293 | CJ55: 56.302868 | CK55: 61.558727 | CL55: 44.785244 | CM55: 325.12671 | CN55: 130.36249 | CO55: 90.608971 | CP55: 96.549622 | CQ55: 0 | CR55: 65.350075 | CS55: 11.721549 | CT55: 54.870872 | CU55: 173.48569 | CV55: 92.903938 | CW55: 2 | CX55: 455 | CY55: 214.86588 | CZ55: 64.946129 | DA55: 23.3249 | DB55: 43.798752 | DC55: 93.111389 | DD55: 682 | DE55: 203 | DF55: 705.61841 | DG55: 98.952621 | DH55: 68.355331 | DI55: 43.426479 | DJ55: 253 | DK55: 144.53799 | DL55: 27.482 | DM55: 60.436001 | DN55: 53.896999 | DO55: 118.35645 | DP55: 17.162001 | DR55: 67 | DS55: 56.200001 | DT55: 14 | DV55: 177 | DW55: 164.02298 | DX55: 11 | DZ55: 53 | EA55: 3 | EB55: 0 | EC55: 1 | ED55: 858.09998 | EE55: 0 | EF55: #NUM! | EG55: #DIV/0! | EH55: 영평소
